<?xml version="1.0" ?>

<sdf version='1.10'>

<world name='Mtracker_demo'>
    <physics name='1ms' type='ignored'>
      <max_step_size>0.001</max_step_size>
      <real_time_factor>1</real_time_factor>
      <real_time_update_rate>1000</real_time_update_rate>
    </physics>
    <plugin name='ignition::gazebo::systems::Sensors' filename='ignition-gazebo-sensors-system' />
    <plugin name='gz::sim::systems::Physics' filename='gz-sim-physics-system'/>
    <plugin name='gz::sim::systems::UserCommands' filename='gz-sim-user-commands-system'/>
    <plugin name='gz::sim::systems::SceneBroadcaster' filename='gz-sim-scene-broadcaster-system'/>
    <gravity>0 0 -9.8000000000000007</gravity>
    <magnetic_field>5.5644999999999998e-06 2.2875799999999999e-05 -4.2388400000000002e-05</magnetic_field>
    <atmosphere type='adiabatic'/>
    <scene>
      <ambient>0.400000006 0.400000006 0.400000006 1</ambient>
      <background>0.699999988 0.699999988 0.699999988 1</background>
      <shadows>true</shadows>
    </scene>
    
<model name='ground_plane'>
      <static>true</static>
      <link name='link'>
        <collision name='collision'>
          <geometry>
            <plane>
              <normal>0 0 1</normal>
              <size>1 1</size>
            </plane>
          </geometry>
          <surface>
            <friction>
              <ode/>
            </friction>
            <bounce/>
            <contact/>
          </surface>
        </collision>
        <visual name='visual'>
          <geometry>
            <plane>
              <normal>0 0 1</normal>
              <size>100 100</size>
            </plane>
          </geometry>
          <material>
            <ambient>0.800000012 0.800000012 0.800000012 1</ambient>
            <diffuse>0.800000012 0.800000012 0.800000012 1</diffuse>
            <specular>0.800000012 0.800000012 0.800000012 1</specular>
          </material>
        </visual>
        <pose>0 0 0 0 0 0</pose>
        <inertial>
          <pose>0 0 0 0 0 0</pose>
          <mass>1</mass>
          <inertia>
            <ixx>1</ixx>
            <ixy>0</ixy>
            <ixz>0</ixz>
            <iyy>1</iyy>
            <iyz>0</iyz>
            <izz>1</izz>
          </inertia>
        </inertial>
        <enable_wind>false</enable_wind>
      </link>
      <pose>0 0 0 0 0 0</pose>
      <self_collide>false</self_collide>
</model>
    
    
<model name='MTracker' canonical_link='chassis'>
      <pose>0 0 0 0 0 3.14</pose>
      <link name='chassis'>
        <pose>0 0 0.2 0 0 0</pose>
        <inertial>
          <mass>1.14395</mass>
          <inertia>
            <ixx>0.002256</ixx>
            <ixy>0</ixy>
            <ixz>0</ixz>
            <iyy>0.002256</iyy>
            <iyz>0</iyz>
            <izz>0.002606</izz>
          </inertia>
          <pose>0 0 0 0 0 0</pose>
        </inertial>
        
        <visual name='visual'>
          <geometry>
            <cylinder>
              <radius>0.0675</radius>
              <length>0.1</length>
            </cylinder>
          </geometry>
          <material>
            <ambient>0 0 1 1</ambient>
            <diffuse>0 0 1 1</diffuse>
            <specular>0 0 1 1</specular>
          </material>
        </visual>
        <collision name='collision'>
          <geometry>
            <cylinder>
              <radius>0.0675</radius>
              <length>0.1</length>
            </cylinder>
          </geometry>
          <surface>
            <friction>
              <ode/>
            </friction>
            <bounce/>
            <contact/>
          </surface>
        </collision>
        <enable_wind>false</enable_wind>
      </link>
      
      <link name = 'camera'>
      <pose relative_to = 'chassis' >0.025 0 0.06 0 -0.2 0</pose>
        <inertial>
          <mass>0.1</mass>
          <inertia>
            <ixx>0.000166667</ixx>
            <iyy>0.000166667</iyy>
            <izz>0.000166667</izz>
          </inertia>
        </inertial>
        <collision name="collision">
          <geometry>
            <box>
              <size>0.01 0.03 0.01</size>
            </box>
          </geometry>
        </collision>
        <visual name="visual">
          <geometry>
            <box>
              <size>0.01 0.03 0.01</size>
            </box>
          </geometry>
        </visual>
        <sensor name="rgbd_camera" type="rgbd_camera">
          <camera>
            <horizontal_fov>1.20428</horizontal_fov>
            <image>
              <width>1280</width>
              <height>720</height>
            </image>
            <clip>
              <near>0.1</near>
              <far>100</far>
            </clip>
          </camera>
          <always_on>1</always_on>
          <update_rate>30</update_rate>
          <visualize>true</visualize>
          <topic>kamera</topic>
        </sensor>
      </link>
      
      <link name='left_wheel'>
        <pose relative_to="chassis">0 0.0725 -0.05 -1.5707 0 0</pose>
        <inertial>
          <mass>0.1</mass>
          <inertia>
            <ixx>0.000016</ixx>
            <ixy>0</ixy>
            <ixz>0</ixz>
            <iyy>0.000016</iyy>
            <iyz>0</iyz>
            <izz>0.000016</izz>
          </inertia>
          <pose>0 0 0 0 0 0</pose>
        </inertial>
        <visual name='visual'>
          <geometry>
            <cylinder>
              <radius>0.03</radius>
              <length>0.01</length>
            </cylinder>
          </geometry>
          <material>
            <ambient>1 0 0 1</ambient>
            <diffuse>1 0 0 1</diffuse>
            <specular>1 0 0 1</specular>
          </material>
        </visual>
        <collision name='collision'>
          <geometry>
            <cylinder>
              <radius>0.03</radius>
              <length>0.01</length>
            </cylinder>
          </geometry>
          <surface>
            <friction>
              <ode/>
            </friction>
            <bounce/>
            <contact/>
          </surface>
        </collision>
        <enable_wind>false</enable_wind>
      </link>
      <link name='right_wheel'>
        <pose relative_to="chassis">0 -0.0725 -0.05 -1.5707 0 0</pose>
        <inertial>
          <mass>1</mass>
          <inertia>
          	<ixx>0.000016</ixx>
		<ixy>0</ixy>
		<ixz>0</ixz>
		<iyy>0.000016</iyy>
		<iyz>0</iyz>
		<izz>0.000031</izz>
	</inertia>
        </inertial>
        <visual name='visual'>
          <geometry>
            <cylinder>
              <radius>0.03</radius>
              <length>0.01</length>
            </cylinder>
          </geometry>
          <material>
            <ambient>1 0 0 1</ambient>
            <diffuse>1 0 0 1</diffuse>
            <specular>1 0 0 1</specular>
          </material>
        </visual>
        <collision name='collision'>
          <geometry>
            <cylinder>
              <radius>0.03</radius>
              <length>0.01</length>
            </cylinder>
          </geometry>
          <surface>
            <friction>
              <ode/>
            </friction>
            <bounce/>
            <contact/>
          </surface>
        </collision>
        <enable_wind>false</enable_wind>
      </link>
      
      <frame name="caster1_frame" attached_to='chassis'>
                <pose>0.045 0 -0.062 0 0 0</pose>
            </frame>
        
            <!--caster wheel-->
            <link name='caster1'>
                <pose relative_to='caster1_frame'/>
                <inertial>
                    <mass>0.05</mass>
                    <inertia>
                        <ixx>0.000003</ixx>
                        <ixy>0</ixy>
                        <ixz>0</ixz>
                        <iyy>0.000003</iyy>
                        <iyz>0</iyz>
                        <izz>0.000003</izz>
                    </inertia>
                </inertial>
                <visual name='visual'>
                    <geometry>
                        <sphere>
                            <radius>0.0125</radius>
                        </sphere>
                    </geometry>
                    <material>
                        <ambient>0 1 0 1</ambient>
                        <diffuse>0 1 0 1</diffuse>
                        <specular>0 1 0 1</specular>
                    </material>
                </visual>
                <collision name='collision'>
                    <geometry>
                        <sphere>
                            <radius>0.0125</radius>
                        </sphere>
                    </geometry>
                </collision>
            </link>
        
            <frame name="caster2_frame" attached_to='chassis'>
                <pose>-0.045 0 -0.062 0 0 0</pose>
            </frame>
        
            <!--caster wheel-->
            <link name='caster2'>
                <pose relative_to='caster2_frame'/>
                <inertial>
                    <mass>0.05</mass>
                    <inertia>
                        <ixx>0.000003</ixx>
                        <ixy>0</ixy>
                        <ixz>0</ixz>
                        <iyy>0.000003</iyy>
                        <iyz>0</iyz>
                        <izz>0.000003</izz>
                    </inertia>
                </inertial>
                <visual name='visual'>
                    <geometry>
                        <sphere>
                            <radius>0.0125</radius>
                        </sphere>
                    </geometry>
                    <material>
                        <ambient>0 1 0 1</ambient>
                        <diffuse>0 1 0 1</diffuse>
                        <specular>0 1 0 1</specular>
                    </material>
                </visual>
                <collision name='collision'>
                    <geometry>
                        <sphere>
                            <radius>0.0125</radius>
                        </sphere>
                    </geometry>
                </collision>
            </link>
      
      <joint name='left_wheel_joint' type='revolute'>
        <pose>0 0 -1.1102230246251565e-16 0 0 0</pose>
        <parent>chassis</parent>
        <child>left_wheel</child>
        <axis>
          <xyz>0 9.6326794747692026e-05 0.99999999536057438</xyz>
          <limit>
            <lower>-1.7976900000000001e+308</lower>
            <upper>1.7976900000000001e+308</upper>
            <effort>inf</effort>
            <velocity>inf</velocity>
            <stiffness>100000000</stiffness>
            <dissipation>1</dissipation>
          </limit>
          <dynamics>
            <spring_reference>0</spring_reference>
            <spring_stiffness>0</spring_stiffness>
            <damping>0</damping>
            <friction>0</friction>
          </dynamics>
        </axis>
      </joint>
      <joint name='right_wheel_joint' type='revolute'>
        <pose>0 0 0 0 0 0</pose>
        <parent>chassis</parent>
        <child>right_wheel</child>
        <axis>
          <xyz>0 9.6326794747692026e-05 0.99999999536057438</xyz>
          <limit>
            <lower>-1.7976900000000001e+308</lower>
            <upper>1.7976900000000001e+308</upper>
            <effort>inf</effort>
            <velocity>inf</velocity>
            <stiffness>100000000</stiffness>
            <dissipation>1</dissipation>
          </limit>
          <dynamics>
            <spring_reference>0</spring_reference>
            <spring_stiffness>0</spring_stiffness>
            <damping>0</damping>
            <friction>0</friction>
          </dynamics>
        </axis>
      </joint>
      <joint name='camera_joint' type='fixed'>
        <pose>0 0 2 0 0 0</pose>
        <parent>chassis</parent>
        <child>camera</child>
        <axis>
          <xyz>0 0 2</xyz>
          <limit>
            <lower>-1.7976900000000001e+308</lower>
            <upper>1.7976900000000001e+308</upper>
            <effort>inf</effort>
            <velocity>inf</velocity>
            <stiffness>100000000</stiffness>
            <dissipation>1</dissipation>
          </limit>
          <dynamics>
            <spring_reference>0</spring_reference>
            <spring_stiffness>0</spring_stiffness>
            <damping>0</damping>
            <friction>0</friction>
          </dynamics>
        </axis>
      </joint>
      <joint name='caster1_wheel' type='ball'>
                <parent>chassis</parent>
                <child>caster1</child>
            </joint>
            
            <joint name='caster2_wheel' type='ball'>
                <parent>chassis</parent>
                <child>caster2</child>
	</joint>
      <plugin filename="ignition-gazebo-diff-drive-system"
        name="ignition::gazebo::systems::DiffDrive">
        <left_joint>left_wheel_joint</left_joint>
        <right_joint>right_wheel_joint</right_joint>
        <wheel_separation>2.4</wheel_separation>
        <wheel_radius>0.6</wheel_radius>
        <odom_publish_frequency>10</odom_publish_frequency>
        <max_linear_acceleration>1</max_linear_acceleration>
        <min_linear_acceleration>-1</min_linear_acceleration>
        <max_angular_acceleration>2</max_angular_acceleration>
        <min_angular_acceleration>-2</min_angular_acceleration>
        <max_linear_velocity>5</max_linear_velocity>
        <min_linear_velocity>-5</min_linear_velocity>
        <max_angular_velocity>5</max_angular_velocity>
        <min_angular_velocity>-5</min_angular_velocity>
     </plugin>
      <static>false</static>
      <self_collide>false</self_collide>
</model>
    
    <include>
      <uri>file:///home/vvoxel/Local_Gazebo_Resources/models/Apriltag36_11_00003</uri>
      <name>tag36_11_00003</name>
      <pose>-1 0 0.25 3.14 1.54 0</pose>
    </include>
    
    <include>
      <uri>file:///home/vvoxel/Local_Gazebo_Resources/models/Apriltag36_11_00004</uri>
      <name>tag36_11_00004</name>
      <pose>0 1 0.25 0 1.54 1.54</pose>
    </include>
    
    <light name='sun' type='directional'>
      <pose>-10 0 10 0 0 0</pose>
      <cast_shadows>true</cast_shadows>
      <intensity>3</intensity>
      <direction>-0.5 0.10000000000000001 -0.90000000000000002</direction>
      <diffuse>0.800000012 0.800000012 0.800000012 1</diffuse>
      <specular>0.200000003 0.200000003 0.200000003 1</specular>
      <attenuation>
        <range>1000</range>
        <linear>0.01</linear>
        <constant>0.90000000000000002</constant>
        <quadratic>0.001</quadratic>
      </attenuation>
      <spot>
        <inner_angle>0</inner_angle>
        <outer_angle>0</outer_angle>
        <falloff>0</falloff>
      </spot>
    </light>
    <gui fullscreen="0">

      <!-- 3D scene -->
      <plugin filename="GzScene3D" name="3D View">
        <ignition-gui>
          <title>3D View</title>
          <property type="bool" key="showTitleBar">false</property>
          <property type="string" key="state">docked</property>
        </ignition-gui>

        <engine>ogre2</engine>
        <scene>scene</scene>
        <ambient_light>0.4 0.4 0.4</ambient_light>
        <background_color>0.8 0.8 0.8</background_color>
        <camera_pose>-6 0 6 0 0.5 0</camera_pose>
      </plugin>

      <!-- World control -->
      <plugin filename="WorldControl" name="World control">
  	<ignition-gui>
    	<title>World control</title>
    	<property type="bool" key="showTitleBar">false</property>
    	<property type="bool" key="resizable">false</property>
    	<property type="double" key="height">72</property>
    	<property type="double" key="width">121</property>
    	<property type="double" key="z">1</property>

    	<property type="string" key="state">docked</property>
    	<property type="string" key="placement">left</property>
  	</ignition-gui>

  	<play_pause>true</play_pause>
  	<step>true</step>
  	<start_paused>true</start_paused>
  	<service>/world/ros_gz/control</service>
  	<stats_topic>/world/ros_gz/stats</stats_topic>
      </plugin>
      
      <plugin filename="ImageDisplay" name="Image Display">
        <ignition-gui>
          <title>Custom: RGB</title>
          <property key="width" type="double">400</property>
          <property key="state" type="string">floating</property>
          <anchors target="3D View">
            <line own="right" target="right"/>
            <line own="top" target="top"/>
          </anchors>
        </ignition-gui>
        <topic>kamera/image</topic>
        <topic_picker>false</topic_picker>
      </plugin>
      
      <plugin filename="TransformControl" name="Transform Control">
        <ignition-gui>
          <title>Transform Control</title>
          <property key="width" type="double">121</property>
          <property key="state" type="string">docked</property>
          <property key="placement" type="string">left</property>
        </ignition-gui>
      </plugin>
      
      <plugin filename="ComponentInspector" name="Component Inspector">
        <ignition-gui>
          <title>Component Inspector</title>
          <property key="width" type="double">400</property>
          <property key="state" type="string">floating</property>
          <anchors target="3D View">
            <line own="right" target="right"/>
            <line own="top" target="top"/>
          </anchors>
        </ignition-gui>
      </plugin>
</gui>

</world>

</sdf>
