<?xml version='1.0' encoding='utf-8'?>
<sdf version="1.10">
  <world name="car_world">
    <physics name="1ms" type="ignored">
      <max_step_size>0.001</max_step_size>
      <real_time_factor>1</real_time_factor>
      <real_time_update_rate>1000</real_time_update_rate>
      </physics>
    <plugin name="gz::sim::systems::Physics" filename="gz-sim-physics-system" />
    <plugin name="gz::sim::systems::UserCommands" filename="gz-sim-user-commands-system" />
    <plugin name="gz::sim::systems::SceneBroadcaster" filename="gz-sim-scene-broadcaster-system" />
    <gravity>0 0 -9.8000000000000007</gravity>
    <magnetic_field>5.5644999999999998e-06 2.2875799999999999e-05 -4.2388400000000002e-05</magnetic_field>
    <atmosphere type="adiabatic" />
    <scene>
      <ambient>0.400000006 0.400000006 0.400000006 1</ambient>
      <background>0.699999988 0.699999988 0.699999988 1</background>
      <shadows>true</shadows>
      </scene>
    <model name="ground_plane">
      <static>true</static>
      <link name="link">
        <collision name="collision">
          <geometry>
            <plane>
              <normal>0 0 1</normal>
              <size>1 1</size>
              </plane>
            </geometry>
          <surface>
            <friction>
              <ode />
              </friction>
            <bounce />
            <contact />
            </surface>
          </collision>
        <visual name="visual">
          <geometry>
            <plane>
              <normal>0 0 1</normal>
              <size>100 100</size>
              </plane>
            </geometry>
          <material>
            <ambient>0.800000012 0.800000012 0.800000012 1</ambient>
            <diffuse>0.800000012 0.800000012 0.800000012 1</diffuse>
            <specular>0.800000012 0.800000012 0.800000012 1</specular>
            </material>
          </visual>
        <pose>0 0 0 0 0 0</pose>
        <inertial>
          <pose>0 0 0 0 0 0</pose>
          <mass>1</mass>
          <inertia>
            <ixx>1</ixx>
            <ixy>0</ixy>
            <ixz>0</ixz>
            <iyy>1</iyy>
            <iyz>0</iyz>
            <izz>1</izz>
            </inertia>
          </inertial>
        <enable_wind>false</enable_wind>
        </link>
      <pose>0 0 0 0 0 0</pose>
      <self_collide>false</self_collide>
      </model>
    <model name="MTracker" canonical_link="chassis">
      <pose>0 0 0 0 0 0</pose>
      <link name="chassis">
        <pose>0 0 0.59999999999999998 0 0 0</pose>
        <inertial>
          <mass>1.14395</mass>
          <inertia>
            <ixx>0.095328999999999997</ixx>
            <ixy>0</ixy>
            <ixz>0</ixz>
            <iyy>0.38131700000000002</iyy>
            <iyz>0</iyz>
            <izz>0.47664600000000001</izz>
            </inertia>
          <pose>0 0 0 0 0 0</pose>
          </inertial>
        <visual name="visual">
          <geometry>
            <cylinder>
              <radius>0.5</radius>
              <length>0.29999999999999999</length>
              </cylinder>
            </geometry>
          <material>
            <ambient>0 0 1 1</ambient>
            <diffuse>0 0 1 1</diffuse>
            <specular>0 0 1 1</specular>
            </material>
          </visual>
        <collision name="collision">
          <geometry>
            <box>
              <size>2 1 0.5</size>
              </box>
            </geometry>
          <surface>
            <friction>
              <ode />
              </friction>
            <bounce />
            <contact />
            </surface>
          </collision>
        <enable_wind>false</enable_wind>
        </link>
      <link name="left_wheel">
        <pose>0 0.55000000000000004 0.59999999999999998 -1.5706999999999995 0 0</pose>
        <inertial>
          <mass>1</mass>
          <inertia>
            <ixx>0.043333000000000003</ixx>
            <ixy>0</ixy>
            <ixz>0</ixz>
            <iyy>0.043333000000000003</iyy>
            <iyz>0</iyz>
            <izz>0.080000000000000002</izz>
            </inertia>
          <pose>0 0 0 0 0 0</pose>
          </inertial>
        <visual name="visual">
          <geometry>
            <cylinder>
              <radius>0.25</radius>
              <length>0.10000000000000001</length>
              </cylinder>
            </geometry>
          <material>
            <ambient>1 0 0 1</ambient>
            <diffuse>1 0 0 1</diffuse>
            <specular>1 0 0 1</specular>
            </material>
          </visual>
        <collision name="collision">
          <geometry>
            <cylinder>
              <radius>0.25</radius>
              <length>0.10000000000000001</length>
              </cylinder>
            </geometry>
          <surface>
            <friction>
              <ode />
              </friction>
            <bounce />
            <contact />
            </surface>
          </collision>
        <enable_wind>false</enable_wind>
        </link>
      <link name="right_wheel">
        <pose>0 -0.55000000000000004 0.59999999999999998 -1.5706999999999995 0 0</pose>
        <inertial>
          <mass>1</mass>
          <inertia>
            <ixx>0.043333000000000003</ixx>
            <ixy>0</ixy>
            <ixz>0</ixz>
            <iyy>0.043333000000000003</iyy>
            <iyz>0</iyz>
            <izz>0.080000000000000002</izz>
            </inertia>
          <pose>0 0 0 0 0 0</pose>
          </inertial>
        <visual name="visual">
          <geometry>
            <cylinder>
              <radius>0.25</radius>
              <length>0.10000000000000001</length>
              </cylinder>
            </geometry>
          <material>
            <ambient>1 0 0 1</ambient>
            <diffuse>1 0 0 1</diffuse>
            <specular>1 0 0 1</specular>
            </material>
          </visual>
        <collision name="collision">
          <geometry>
            <cylinder>
              <radius>0.25</radius>
              <length>0.10000000000000001</length>
              </cylinder>
            </geometry>
          <surface>
            <friction>
              <ode />
              </friction>
            <bounce />
            <contact />
            </surface>
          </collision>
        <enable_wind>false</enable_wind>
        </link>
      <frame name="caster_frame" attached_to="chassis">
        <pose>0.80000000000000004 0 -0.20000000000000001 0 0 0</pose>
        </frame>
      <joint name="left_wheel_joint" type="revolute">
        <pose>0 0 -1.1102230246251565e-16 0 0 0</pose>
        <parent>chassis</parent>
        <child>left_wheel</child>
        <axis>
          <xyz>0 9.6326794747692026e-05 0.99999999536057438</xyz>
          <limit>
            <lower>-1.7976900000000001e+308</lower>
            <upper>1.7976900000000001e+308</upper>
            <effort>inf</effort>
            <velocity>inf</velocity>
            <stiffness>100000000</stiffness>
            <dissipation>1</dissipation>
            </limit>
          <dynamics>
            <spring_reference>0</spring_reference>
            <spring_stiffness>0</spring_stiffness>
            <damping>0</damping>
            <friction>0</friction>
            </dynamics>
          </axis>
        </joint>
      <joint name="right_wheel_joint" type="revolute">
        <pose>0 0 0 0 0 0</pose>
        <parent>chassis</parent>
        <child>right_wheel</child>
        <axis>
          <xyz>0 9.6326794747692026e-05 0.99999999536057438</xyz>
          <limit>
            <lower>-1.7976900000000001e+308</lower>
            <upper>1.7976900000000001e+308</upper>
            <effort>inf</effort>
            <velocity>inf</velocity>
            <stiffness>100000000</stiffness>
            <dissipation>1</dissipation>
            </limit>
          <dynamics>
            <spring_reference>0</spring_reference>
            <spring_stiffness>0</spring_stiffness>
            <damping>0</damping>
            <friction>0</friction>
            </dynamics>
          </axis>
        </joint>
      <plugin name="gz::sim::systems::DiffDrive" filename="gz-sim-diff-drive-system">
        <left_joint>left_wheel_joint</left_joint>
        <right_joint>right_wheel_joint</right_joint>
        <wheel_separation>2.4</wheel_separation>
        <wheel_radius>0.6</wheel_radius>
        <odom_publish_frequency>1</odom_publish_frequency>
        <topic>cmd_vel</topic>
        </plugin>
      <static>false</static>
      <self_collide>false</self_collide>
      <link name="link">
        <pose>0.05 0.05 0.05 0 0 0</pose>
        <inertial>
          <mass>0.1</mass>
          <inertia>
            <ixx>0.000166667</ixx>
            <iyy>0.000166667</iyy>
            <izz>0.000166667</izz>
          </inertia>
        </inertial>
        <collision name="collision">
          <geometry>
            <box>
              <size>0.1 0.1 0.1</size>
            </box>
          </geometry>
        </collision>
        <visual name="visual">
          <geometry>
            <box>
              <size>0.1 0.1 0.1</size>
            </box>
          </geometry>
        </visual>
        <sensor name="rgbd_camera" type="rgbd_camera">
          <camera>
            <horizontal_fov>1.047</horizontal_fov>
            <image>
              <width>320</width>
              <height>240</height>
            </image>
            <clip>
              <near>0.1</near>
              <far>100</far>
            </clip>
          </camera>
          <always_on>1</always_on>
          <update_rate>30</update_rate>
          <visualize>true</visualize>
          <topic>custom_params</topic>
          <plugin
            filename="RosGzPointCloud"
            name="ros_gz_point_cloud::PointCloud">
            <namespace>custom_params</namespace>
            <topic>pc2</topic>
            <frame_id>map</frame_id>
          </plugin>
        </sensor>
      </link>
      </model>
    <include>
      <uri>file:///home/vvoxel/Local_Gazebo_Resources/models/Apriltag36_11_00003</uri>
      <name>tag36_11_00003</name>
      <pose>7.8574423789978027 1.119309663772583 1.1188147068023682 3.1415900000058401 1.5415899677749065 3.1415800000060901</pose>
      </include>
    <light name="sun" type="directional">
      <pose>0 0 10 0 0 0</pose>
      <cast_shadows>true</cast_shadows>
      <intensity>1</intensity>
      <direction>-0.5 0.10000000000000001 -0.90000000000000002</direction>
      <diffuse>0.800000012 0.800000012 0.800000012 1</diffuse>
      <specular>0.200000003 0.200000003 0.200000003 1</specular>
      <attenuation>
        <range>1000</range>
        <linear>0.01</linear>
        <constant>0.90000000000000002</constant>
        <quadratic>0.001</quadratic>
        </attenuation>
      <spot>
        <inner_angle>0</inner_angle>
        <outer_angle>0</outer_angle>
        <falloff>0</falloff>
        </spot>
      </light>
    <gui>
      <plugin filename="ImageDisplay" name="Image Display">
        <ignition-gui>
          <title>Default: RGB</title>
          <property key="width" type="double">400</property>
          <property key="height" type="double">315</property>
          <property key="state" type="string">floating</property>
          <anchors target="3D View">
            <line own="right" target="right"/>
            <line own="bottom" target="bottom"/>
          </anchors>
        </ignition-gui>
        <topic>rgbd_camera/image</topic>
        <topic_picker>false</topic_picker>
      </plugin>
      </gui>
    </world>
  </sdf>
